## 错误处理

### 捕获错误

Python所有的错误都是从`BaseException`类派生的

[https:\/\/docs.python.org\/3\/library\/exceptions.html\#exception-hierarchy](https://docs.python.org/3/library/exceptions.html#exception-hierarchy) 

```
try:
    print('try...')
    r = 10 / int('2')
    print('result:', r)
except ValueError as e:
    print('ValueError:', e)
except ZeroDivisionError as e:
    print('ZeroDivisionError:', e)
else:
    print('no error!')
finally:
    print('finally...')
print('END')
```

```
try:
    foo()
except ValueError as e:
    print('ValueError')
except UnicodeError as e:
    print('UnicodeError')
```

第二个`except`永远也捕获不到`UnicodeError`，因为`UnicodeError`是`ValueError`的子类 

可以跨越多层调用 

```
def foo(s):
    return 10 / int(s)

def bar(s):
    return foo(s) * 2

def main():
    try:
        bar('0')
    except Exception as e:
        print('Error:', e)
    finally:
        print('finally...')
```

如果错误没有被捕获，它就会一直往上抛，最后被Python解释器捕获，打印一个错误信息，然后程序退出 

### 记录错误

```
# err_logging.py

import logging

def foo(s):
    return 10 / int(s)

def bar(s):
    return foo(s) * 2

def main():
    try:
        bar('0')
    except Exception as e:
        logging.exception(e)

main()
print('END')
```

同样是出错，但程序打印完错误信息后会继续执行，并正常退出 

### 抛出错误

```
# err_raise.py
class FooError(ValueError):
    pass

def foo(s):
    n = int(s)
    if n==0:
        raise FooError('invalid value: %s' % s)
    return 10 / n

foo('0')
```

```
# err_reraise.py

def foo(s):
    n = int(s)
    if n==0:
        raise ValueError('invalid value: %s' % s)
    return 10 / n

def bar():
    try:
        foo('0')
    except ValueError as e:
        print('ValueError!')
        raise

bar()
```

继续往上抛，让顶层调用者去处理



